Traceback (most recent call last):
  File "C:\Users\lcisn\AppData\Local\Programs\Python\Python38\lib\site-packages\jupyter_cache\executors\utils.py", line 58, in single_nb_execution
    executenb(
  File "C:\Users\lcisn\AppData\Local\Programs\Python\Python38\lib\site-packages\nbclient\client.py", line 1263, in execute
    return NotebookClient(nb=nb, resources=resources, km=km, **kwargs).execute()
  File "C:\Users\lcisn\AppData\Local\Programs\Python\Python38\lib\site-packages\nbclient\util.py", line 85, in wrapped
    return just_run(coro(*args, **kwargs))
  File "C:\Users\lcisn\AppData\Local\Programs\Python\Python38\lib\site-packages\nbclient\util.py", line 60, in just_run
    return loop.run_until_complete(coro)
  File "C:\Users\lcisn\AppData\Local\Programs\Python\Python38\lib\asyncio\base_events.py", line 616, in run_until_complete
    return future.result()
  File "C:\Users\lcisn\AppData\Local\Programs\Python\Python38\lib\site-packages\nbclient\client.py", line 701, in async_execute
    await self.async_execute_cell(
  File "C:\Users\lcisn\AppData\Local\Programs\Python\Python38\lib\site-packages\nbclient\client.py", line 1019, in async_execute_cell
    await self._check_raise_for_error(cell, cell_index, exec_reply)
  File "C:\Users\lcisn\AppData\Local\Programs\Python\Python38\lib\site-packages\nbclient\client.py", line 913, in _check_raise_for_error
    raise CellExecutionError.from_cell_and_msg(cell, exec_reply_content)
nbclient.exceptions.CellExecutionError: An error occurred while executing the following cell:
------------------
from ipywidgets import interact
import ipywidgets as ipywidgets

def f(x):
   return(x)

interact(f,x)

------------------

[1;31m---------------------------------------------------------------------------[0m
[1;31mTypeError[0m                                 Traceback (most recent call last)
Cell [1;32mIn [4], line 7[0m
[0;32m      4[0m [38;5;28;01mdef[39;00m [38;5;21mf[39m(x):
[0;32m      5[0m    [38;5;28;01mreturn[39;00m(x)
[1;32m----> 7[0m interact(f,x)

[1;31mTypeError[0m: __call__() takes from 1 to 2 positional arguments but 3 were given
TypeError: __call__() takes from 1 to 2 positional arguments but 3 were given

